{
 "cells": [
  {
   "cell_type": "markdown",
   "id": "677770f8",
   "metadata": {},
   "source": [
    "<h1 align=\"center\">Python Errors and Exception handling</h1>\n",
    "\n",
    "\n",
    "No matter your skill as a programmer, you will eventually make a coding mistake.\n",
    "\n",
    "![image exception](./data/python3-exception-image.jpg)\n",
    "\n",
    "Such mistakes come in three basic flavors:\n",
    "- *Syntax errors:* Errors where the code is not valid Python (generally easy to fix)\n",
    "- *Runtime errors:* Errors where syntactically valid code fails to execute, perhaps due to invalid user input (sometimes easy to fix)\n",
    "- *Semantic errors:* Errors in logic: code executes without a problem, but the result is not what you expect (often very difficult to track-down and fix)\n",
    "\n",
    "Here we're going to focus on how to deal cleanly with runtime errors. As we'll see, Python handles runtime errors via its exception handling framework."
   ]
  },
  {
   "cell_type": "markdown",
   "id": "223ab1ef",
   "metadata": {},
   "source": [
    "## Exceptions\n",
    "\n",
    "Exceptions are a tool that programmers use to describe errors or faults that are fatal to the program.\n",
    "\n",
    "Exceptions can occur due to programming errors, user errors, or simply unexpected conditions like no internet access.\n",
    "\n",
    "Exceptions themselves are simply objects that contain information about what went wrong.\n",
    "\n",
    "Exceptions are usually defined by their `type` - which describes broadly the class of exception that occurred, and by a `message` that says specifically what happened. Here are a few common exception types:\n",
    "- !!!!!`SyntaxError`: raised when the programmer has made a mistake typing Python code correctly.\n",
    "- `AttributeError`: attempting to access an attribute on an object that does not exist\n",
    "- `KeyError`: attempting to access a key in a dictionary that does not exist\n",
    "- `TypeError`: raised when an argument to a function is not the right type (e.g. a str instead of int)\n",
    "- `ValueError`: when an argument to a function is the right type but not in the right domain (e.g. an empty string)\n",
    "- `ImportError`: raised when an import fails\n",
    "- `IOError`: raised when Python cannot access a file correctly on disk\n",
    "\n",
    "\n",
    "\n",
    "![exception-heirarchy](data/exceptions-types.jpg)"
   ]
  },
  {
   "cell_type": "markdown",
   "id": "8c33202c",
   "metadata": {},
   "source": [
    "## Runtime Errors\n",
    "\n",
    "During your coding journey in Python, you've likely come across runtime errors. They can happen in a lot of ways.\n",
    "\n",
    "For example, if you try to reference an undefined variable:"
   ]
  },
  {
   "cell_type": "code",
   "execution_count": 1,
   "id": "2f77d9d0",
   "metadata": {},
   "outputs": [
    {
     "ename": "NameError",
     "evalue": "name 'Z' is not defined",
     "output_type": "error",
     "traceback": [
      "\u001b[0;31m---------------------------------------------------------------------------\u001b[0m",
      "\u001b[0;31mNameError\u001b[0m                                 Traceback (most recent call last)",
      "Input \u001b[0;32mIn [1]\u001b[0m, in \u001b[0;36m<cell line: 1>\u001b[0;34m()\u001b[0m\n\u001b[0;32m----> 1\u001b[0m \u001b[38;5;28mprint\u001b[39m(\u001b[43mZ\u001b[49m)\n",
      "\u001b[0;31mNameError\u001b[0m: name 'Z' is not defined"
     ]
    }
   ],
   "source": [
    "print(Z)"
   ]
  },
  {
   "cell_type": "markdown",
   "id": "2cb886a1",
   "metadata": {},
   "source": [
    "Or if you try an operation that's not defined:"
   ]
  },
  {
   "cell_type": "code",
   "execution_count": 3,
   "id": "72d0c764",
   "metadata": {},
   "outputs": [
    {
     "ename": "TypeError",
     "evalue": "can only concatenate str (not \"int\") to str",
     "output_type": "error",
     "traceback": [
      "\u001b[0;31m---------------------------------------------------------------------------\u001b[0m",
      "\u001b[0;31mTypeError\u001b[0m                                 Traceback (most recent call last)",
      "Input \u001b[0;32mIn [3]\u001b[0m, in \u001b[0;36m<cell line: 1>\u001b[0;34m()\u001b[0m\n\u001b[0;32m----> 1\u001b[0m \u001b[38;5;124;43m\"\u001b[39;49m\u001b[38;5;124;43mit\u001b[39;49m\u001b[38;5;124;43m'\u001b[39;49m\u001b[38;5;124;43ms\u001b[39;49m\u001b[38;5;124;43m\"\u001b[39;49m\u001b[43m \u001b[49m\u001b[38;5;241;43m+\u001b[39;49m\u001b[43m \u001b[49m\u001b[38;5;241;43m3\u001b[39;49m \u001b[38;5;241m+\u001b[39m \u001b[38;5;124m'\u001b[39m\u001b[38;5;124mPM\u001b[39m\u001b[38;5;124m'\u001b[39m\n",
      "\u001b[0;31mTypeError\u001b[0m: can only concatenate str (not \"int\") to str"
     ]
    }
   ],
   "source": [
    "\"it's\" + 3 + 'PM'"
   ]
  },
  {
   "cell_type": "code",
   "execution_count": 4,
   "id": "5e4118a6",
   "metadata": {},
   "outputs": [
    {
     "ename": "TypeError",
     "evalue": "unsupported operand type(s) for +: 'int' and 'str'",
     "output_type": "error",
     "traceback": [
      "\u001b[0;31m---------------------------------------------------------------------------\u001b[0m",
      "\u001b[0;31mTypeError\u001b[0m                                 Traceback (most recent call last)",
      "Input \u001b[0;32mIn [4]\u001b[0m, in \u001b[0;36m<cell line: 1>\u001b[0;34m()\u001b[0m\n\u001b[0;32m----> 1\u001b[0m \u001b[38;5;241;43m3\u001b[39;49m\u001b[43m \u001b[49m\u001b[38;5;241;43m+\u001b[39;49m\u001b[43m \u001b[49m\u001b[38;5;124;43m\"\u001b[39;49m\u001b[38;5;124;43mPotatos\u001b[39;49m\u001b[38;5;124;43m\"\u001b[39;49m\n",
      "\u001b[0;31mTypeError\u001b[0m: unsupported operand type(s) for +: 'int' and 'str'"
     ]
    }
   ],
   "source": [
    "3 + \"Potatos\""
   ]
  },
  {
   "cell_type": "markdown",
   "id": "3a22da4f",
   "metadata": {},
   "source": [
    "Or you might be trying to compute a mathematically ill-defined result:"
   ]
  },
  {
   "cell_type": "code",
   "execution_count": 5,
   "id": "52566dfe",
   "metadata": {},
   "outputs": [
    {
     "ename": "ZeroDivisionError",
     "evalue": "division by zero",
     "output_type": "error",
     "traceback": [
      "\u001b[0;31m---------------------------------------------------------------------------\u001b[0m",
      "\u001b[0;31mZeroDivisionError\u001b[0m                         Traceback (most recent call last)",
      "Input \u001b[0;32mIn [5]\u001b[0m, in \u001b[0;36m<cell line: 1>\u001b[0;34m()\u001b[0m\n\u001b[0;32m----> 1\u001b[0m \u001b[38;5;241;43m5\u001b[39;49m\u001b[43m \u001b[49m\u001b[38;5;241;43m/\u001b[39;49m\u001b[43m \u001b[49m\u001b[38;5;241;43m0\u001b[39;49m\n",
      "\u001b[0;31mZeroDivisionError\u001b[0m: division by zero"
     ]
    }
   ],
   "source": [
    "5 / 0"
   ]
  },
  {
   "cell_type": "markdown",
   "id": "1f4b6bc8",
   "metadata": {},
   "source": [
    "Or maybe you're trying to access a sequence element that doesn't exist:"
   ]
  },
  {
   "cell_type": "code",
   "execution_count": 6,
   "id": "b50e88a2",
   "metadata": {
    "scrolled": true
   },
   "outputs": [
    {
     "ename": "IndexError",
     "evalue": "list index out of range",
     "output_type": "error",
     "traceback": [
      "\u001b[0;31m---------------------------------------------------------------------------\u001b[0m",
      "\u001b[0;31mIndexError\u001b[0m                                Traceback (most recent call last)",
      "Input \u001b[0;32mIn [6]\u001b[0m, in \u001b[0;36m<cell line: 2>\u001b[0;34m()\u001b[0m\n\u001b[1;32m      1\u001b[0m data \u001b[38;5;241m=\u001b[39m [\u001b[38;5;241m1\u001b[39m, \u001b[38;5;241m3\u001b[39m, \u001b[38;5;241m5\u001b[39m, \u001b[38;5;241m8\u001b[39m]\n\u001b[0;32m----> 2\u001b[0m \u001b[43mdata\u001b[49m\u001b[43m[\u001b[49m\u001b[38;5;241;43m4\u001b[39;49m\u001b[43m]\u001b[49m\n",
      "\u001b[0;31mIndexError\u001b[0m: list index out of range"
     ]
    }
   ],
   "source": [
    "data = [1, 3, 5, 8]\n",
    "data[4]"
   ]
  },
  {
   "cell_type": "markdown",
   "id": "b83152fd",
   "metadata": {},
   "source": [
    "*Note:* Python is kind enough to not simply indicate that an error happened, but to spit out a meaningful exception that includes information about what exactly went wrong, along with the exact line of code where the error happened. Having access to meaningful errors like this is immensely useful when trying to trace the root of problems in your code."
   ]
  },
  {
   "cell_type": "markdown",
   "id": "231fb706",
   "metadata": {},
   "source": [
    "## Catching Exceptions: `try` and `except`:\n",
    "\n",
    "If the exception was caused by a programming error, the developer can simply change the code to make it correct. However, if the exception was created by bad user input or by a bad environmental condition (e.g. the wireless is down), then you don't want to crash the program. Instead you want to provide feedback and allow the user to fix the problem or try again. Therefore in your code, you can catch exceptions at the place they occur using the following syntax:\n"
   ]
  },
  {
   "cell_type": "code",
   "execution_count": 7,
   "id": "ea18349e",
   "metadata": {},
   "outputs": [
    {
     "name": "stdout",
     "output_type": "stream",
     "text": [
      "this gets executed first\n"
     ]
    }
   ],
   "source": [
    "try:\n",
    "    print(\"this gets executed first\")\n",
    "except:\n",
    "    print(\"this gets executed only if there is an error\")"
   ]
  },
  {
   "cell_type": "markdown",
   "id": "533f6704",
   "metadata": {},
   "source": [
    "Note that the second block here did not get executed: this is because the first block did not return an error. Let's put a problematic statement in the `try` block and see what happens:"
   ]
  },
  {
   "cell_type": "code",
   "execution_count": 8,
   "id": "ed049cb5",
   "metadata": {},
   "outputs": [
    {
     "name": "stdout",
     "output_type": "stream",
     "text": [
      "let's try something:\n",
      "something bad happened!\n"
     ]
    }
   ],
   "source": [
    "try:\n",
    "    print(\"let's try something:\")\n",
    "    x = 1 / 0\n",
    "except:\n",
    "    print(\"something bad happened!\")"
   ]
  },
  {
   "cell_type": "markdown",
   "id": "4d0f4703",
   "metadata": {},
   "source": [
    "Here we see that when the error was raised in the `try` statement (in this case, a `ZeroDivisionError`), the error was caught, and the `except` statement was executed.\n",
    "\n",
    "One way this is often used is to check user input within a function or another piece of code. For example, we might wish to have a function that catches zero-division and returns some other value, perhaps a suitably large number like **10<sup>100</sup>**:"
   ]
  },
  {
   "cell_type": "code",
   "execution_count": 10,
   "id": "0a1e8014",
   "metadata": {},
   "outputs": [],
   "source": [
    "def safe_divide(a, b):\n",
    "    try:\n",
    "        return a / b\n",
    "    except:\n",
    "        return 1E100"
   ]
  },
  {
   "cell_type": "code",
   "execution_count": 11,
   "id": "d9998086",
   "metadata": {},
   "outputs": [
    {
     "data": {
      "text/plain": [
       "0.5"
      ]
     },
     "execution_count": 11,
     "metadata": {},
     "output_type": "execute_result"
    }
   ],
   "source": [
    "safe_divide(1, 2)"
   ]
  },
  {
   "cell_type": "code",
   "execution_count": 12,
   "id": "0c450837",
   "metadata": {},
   "outputs": [
    {
     "data": {
      "text/plain": [
       "1e+100"
      ]
     },
     "execution_count": 12,
     "metadata": {},
     "output_type": "execute_result"
    }
   ],
   "source": [
    "safe_divide(2, 0)"
   ]
  },
  {
   "cell_type": "markdown",
   "id": "9cb410d4",
   "metadata": {},
   "source": [
    "There is a subtle problem with this code, though: what happens when another type of exception comes up? For example, this is probably not what we intended:"
   ]
  },
  {
   "cell_type": "code",
   "execution_count": 13,
   "id": "270ec022",
   "metadata": {},
   "outputs": [
    {
     "data": {
      "text/plain": [
       "1e+100"
      ]
     },
     "execution_count": 13,
     "metadata": {},
     "output_type": "execute_result"
    }
   ],
   "source": [
    "safe_divide (1, '2')"
   ]
  },
  {
   "cell_type": "markdown",
   "id": "e4d2e699",
   "metadata": {},
   "source": [
    "Dividing an integer and a string raises a `TypeError`, which our over-zealous code caught and assumed was a `ZeroDivisionError`! For this reason, it's nearly always a better idea to catch exceptions explicitly:"
   ]
  },
  {
   "cell_type": "code",
   "execution_count": 14,
   "id": "e043e4c8",
   "metadata": {},
   "outputs": [],
   "source": [
    "def safe_divide(a, b):\n",
    "    try:\n",
    "        return a / b\n",
    "    except ZeroDivisionError:\n",
    "        return 1E100"
   ]
  },
  {
   "cell_type": "code",
   "execution_count": 15,
   "id": "761130d1",
   "metadata": {},
   "outputs": [
    {
     "data": {
      "text/plain": [
       "1e+100"
      ]
     },
     "execution_count": 15,
     "metadata": {},
     "output_type": "execute_result"
    }
   ],
   "source": [
    "safe_divide(1, 0)"
   ]
  },
  {
   "cell_type": "code",
   "execution_count": 16,
   "id": "77d01e77",
   "metadata": {},
   "outputs": [
    {
     "ename": "TypeError",
     "evalue": "unsupported operand type(s) for /: 'int' and 'str'",
     "output_type": "error",
     "traceback": [
      "\u001b[0;31m---------------------------------------------------------------------------\u001b[0m",
      "\u001b[0;31mTypeError\u001b[0m                                 Traceback (most recent call last)",
      "Input \u001b[0;32mIn [16]\u001b[0m, in \u001b[0;36m<cell line: 1>\u001b[0;34m()\u001b[0m\n\u001b[0;32m----> 1\u001b[0m \u001b[43msafe_divide\u001b[49m\u001b[43m(\u001b[49m\u001b[38;5;241;43m1\u001b[39;49m\u001b[43m,\u001b[49m\u001b[43m \u001b[49m\u001b[38;5;124;43m'\u001b[39;49m\u001b[38;5;124;43m2\u001b[39;49m\u001b[38;5;124;43m'\u001b[39;49m\u001b[43m)\u001b[49m\n",
      "Input \u001b[0;32mIn [14]\u001b[0m, in \u001b[0;36msafe_divide\u001b[0;34m(a, b)\u001b[0m\n\u001b[1;32m      1\u001b[0m \u001b[38;5;28;01mdef\u001b[39;00m \u001b[38;5;21msafe_divide\u001b[39m(a, b):\n\u001b[1;32m      2\u001b[0m     \u001b[38;5;28;01mtry\u001b[39;00m:\n\u001b[0;32m----> 3\u001b[0m         \u001b[38;5;28;01mreturn\u001b[39;00m \u001b[43ma\u001b[49m\u001b[43m \u001b[49m\u001b[38;5;241;43m/\u001b[39;49m\u001b[43m \u001b[49m\u001b[43mb\u001b[49m\n\u001b[1;32m      4\u001b[0m     \u001b[38;5;28;01mexcept\u001b[39;00m \u001b[38;5;167;01mZeroDivisionError\u001b[39;00m:\n\u001b[1;32m      5\u001b[0m         \u001b[38;5;28;01mreturn\u001b[39;00m \u001b[38;5;241m1E100\u001b[39m\n",
      "\u001b[0;31mTypeError\u001b[0m: unsupported operand type(s) for /: 'int' and 'str'"
     ]
    }
   ],
   "source": [
    "safe_divide(1, '2')"
   ]
  },
  {
   "cell_type": "markdown",
   "id": "3716a488",
   "metadata": {},
   "source": [
    "We're now catching `zero-division` errors only, and letting all other errors pass through un-modified."
   ]
  },
  {
   "cell_type": "markdown",
   "id": "e17c0d5b",
   "metadata": {},
   "source": [
    "## Raising Exceptions: ``raise``\n",
    "We've seen how valuable it is to have informative exceptions when using parts of the Python language.\n",
    "It's equally valuable to make use of informative exceptions within the code you write, so that users of your code (foremost yourself!) can figure out what caused their errors.\n",
    "\n",
    "The way you raise your own exceptions is with the ``raise`` statement. For example:"
   ]
  },
  {
   "cell_type": "code",
   "execution_count": 16,
   "id": "9b9ceff6",
   "metadata": {},
   "outputs": [
    {
     "ename": "RuntimeError",
     "evalue": "my error message",
     "output_type": "error",
     "traceback": [
      "\u001b[0;31m---------------------------------------------------------------------------\u001b[0m",
      "\u001b[0;31mRuntimeError\u001b[0m                              Traceback (most recent call last)",
      "\u001b[0;32m<ipython-input-16-c6a4c1ed2f34>\u001b[0m in \u001b[0;36m<module>\u001b[0;34m()\u001b[0m\n\u001b[0;32m----> 1\u001b[0;31m \u001b[0;32mraise\u001b[0m \u001b[0mRuntimeError\u001b[0m\u001b[0;34m(\u001b[0m\u001b[0;34m\"my error message\"\u001b[0m\u001b[0;34m)\u001b[0m\u001b[0;34m\u001b[0m\u001b[0m\n\u001b[0m",
      "\u001b[0;31mRuntimeError\u001b[0m: my error message"
     ]
    }
   ],
   "source": [
    "raise RuntimeError(\"my error message\")"
   ]
  },
  {
   "cell_type": "markdown",
   "id": "6f6751da",
   "metadata": {},
   "source": [
    "As an example of where this might be useful, let's return to our ``fibonacci`` function that we defined previously:"
   ]
  },
  {
   "cell_type": "code",
   "execution_count": 17,
   "id": "b8c665ec",
   "metadata": {},
   "outputs": [],
   "source": [
    "def fibonacci(N):\n",
    "    L = []\n",
    "    a, b = 0, 1\n",
    "    while len(L) < N:\n",
    "        a, b = b, a + b\n",
    "        L.append(a)\n",
    "    return L"
   ]
  },
  {
   "cell_type": "markdown",
   "id": "2f527280",
   "metadata": {},
   "source": [
    "One potential problem here is that the input value could be negative.\n",
    "This will not currently cause any error in our function, but we might want to let the user know that a negative ``N`` is not supported.\n",
    "Errors stemming from invalid parameter values, by convention, lead to a ``ValueError`` being raised:"
   ]
  },
  {
   "cell_type": "code",
   "execution_count": 18,
   "id": "8cff7995",
   "metadata": {},
   "outputs": [],
   "source": [
    "def fibonacci(N):\n",
    "    if N < 0:\n",
    "        raise ValueError(\"N must be non-negative\")\n",
    "    L = []\n",
    "    a, b = 0, 1\n",
    "    while len(L) < N:\n",
    "        a, b = b, a + b\n",
    "        L.append(a)\n",
    "    return L"
   ]
  },
  {
   "cell_type": "code",
   "execution_count": 19,
   "id": "3fbe4e0c",
   "metadata": {},
   "outputs": [
    {
     "data": {
      "text/plain": [
       "[1, 1, 2, 3, 5, 8, 13, 21, 34, 55]"
      ]
     },
     "execution_count": 19,
     "metadata": {},
     "output_type": "execute_result"
    }
   ],
   "source": [
    "fibonacci(10)"
   ]
  },
  {
   "cell_type": "code",
   "execution_count": 20,
   "id": "e4d7b788",
   "metadata": {},
   "outputs": [
    {
     "ename": "ValueError",
     "evalue": "N must be non-negative",
     "output_type": "error",
     "traceback": [
      "\u001b[0;31m---------------------------------------------------------------------------\u001b[0m",
      "\u001b[0;31mValueError\u001b[0m                                Traceback (most recent call last)",
      "\u001b[0;32m<ipython-input-20-3d291499cfa7>\u001b[0m in \u001b[0;36m<module>\u001b[0;34m()\u001b[0m\n\u001b[0;32m----> 1\u001b[0;31m \u001b[0mfibonacci\u001b[0m\u001b[0;34m(\u001b[0m\u001b[0;34m-\u001b[0m\u001b[0;36m10\u001b[0m\u001b[0;34m)\u001b[0m\u001b[0;34m\u001b[0m\u001b[0m\n\u001b[0m",
      "\u001b[0;32m<ipython-input-18-01d0cf168d63>\u001b[0m in \u001b[0;36mfibonacci\u001b[0;34m(N)\u001b[0m\n\u001b[1;32m      1\u001b[0m \u001b[0;32mdef\u001b[0m \u001b[0mfibonacci\u001b[0m\u001b[0;34m(\u001b[0m\u001b[0mN\u001b[0m\u001b[0;34m)\u001b[0m\u001b[0;34m:\u001b[0m\u001b[0;34m\u001b[0m\u001b[0m\n\u001b[1;32m      2\u001b[0m     \u001b[0;32mif\u001b[0m \u001b[0mN\u001b[0m \u001b[0;34m<\u001b[0m \u001b[0;36m0\u001b[0m\u001b[0;34m:\u001b[0m\u001b[0;34m\u001b[0m\u001b[0m\n\u001b[0;32m----> 3\u001b[0;31m         \u001b[0;32mraise\u001b[0m \u001b[0mValueError\u001b[0m\u001b[0;34m(\u001b[0m\u001b[0;34m\"N must be non-negative\"\u001b[0m\u001b[0;34m)\u001b[0m\u001b[0;34m\u001b[0m\u001b[0m\n\u001b[0m\u001b[1;32m      4\u001b[0m     \u001b[0mL\u001b[0m \u001b[0;34m=\u001b[0m \u001b[0;34m[\u001b[0m\u001b[0;34m]\u001b[0m\u001b[0;34m\u001b[0m\u001b[0m\n\u001b[1;32m      5\u001b[0m     \u001b[0ma\u001b[0m\u001b[0;34m,\u001b[0m \u001b[0mb\u001b[0m \u001b[0;34m=\u001b[0m \u001b[0;36m0\u001b[0m\u001b[0;34m,\u001b[0m \u001b[0;36m1\u001b[0m\u001b[0;34m\u001b[0m\u001b[0m\n",
      "\u001b[0;31mValueError\u001b[0m: N must be non-negative"
     ]
    }
   ],
   "source": [
    "fibonacci(-10)"
   ]
  },
  {
   "cell_type": "markdown",
   "id": "b0817ec9",
   "metadata": {},
   "source": [
    "Now the user knows exactly why the input is invalid, and could even use a ``try``...``except`` block to handle it!"
   ]
  },
  {
   "cell_type": "code",
   "execution_count": 21,
   "id": "ca50ab9f",
   "metadata": {},
   "outputs": [
    {
     "name": "stdout",
     "output_type": "stream",
     "text": [
      "trying this...\n",
      "Bad value: need to do something else\n"
     ]
    }
   ],
   "source": [
    "N = -10\n",
    "try:\n",
    "    print(\"trying this...\")\n",
    "    print(fibonacci(N))\n",
    "except ValueError:\n",
    "    print(\"Bad value: need to do something else\")"
   ]
  },
  {
   "cell_type": "markdown",
   "id": "775d060b",
   "metadata": {},
   "source": [
    "## Diving Deeper into Exceptions\n",
    "\n",
    "Briefly, I want to mention here some other concepts you might run into.\n",
    "I'll not go into detail on these concepts and how and why to use them, but instead simply show you the syntax so you can explore more on your own."
   ]
  },
  {
   "cell_type": "markdown",
   "id": "589120e2",
   "metadata": {},
   "source": [
    "### Accessing the error message\n",
    "\n",
    "Sometimes in a ``try``...``except`` statement, you would like to be able to work with the error message itself.\n",
    "This can be done with the ``as`` keyword:"
   ]
  },
  {
   "cell_type": "code",
   "execution_count": 22,
   "id": "bcf4720c",
   "metadata": {},
   "outputs": [
    {
     "name": "stdout",
     "output_type": "stream",
     "text": [
      "Error class is:   <class 'ZeroDivisionError'>\n",
      "Error message is: division by zero\n"
     ]
    }
   ],
   "source": [
    "try:\n",
    "    x = 1 / 0\n",
    "except ZeroDivisionError as err:\n",
    "    print(\"Error class is:  \", type(err))\n",
    "    print(\"Error message is:\", err)"
   ]
  },
  {
   "cell_type": "markdown",
   "id": "f419b92e",
   "metadata": {},
   "source": [
    "With this pattern, you can further customize the exception handling of your function."
   ]
  },
  {
   "cell_type": "markdown",
   "id": "9de3e49e",
   "metadata": {},
   "source": [
    "### Defining custom exceptions\n",
    "In addition to built-in exceptions, it is possible to define custom exceptions through *class inheritance*.\n",
    "For instance, if you want a special kind of ``ValueError``, you can do this:"
   ]
  },
  {
   "cell_type": "code",
   "execution_count": 23,
   "id": "ddd45e67",
   "metadata": {},
   "outputs": [
    {
     "ename": "MySpecialError",
     "evalue": "here's the message",
     "output_type": "error",
     "traceback": [
      "\u001b[0;31m---------------------------------------------------------------------------\u001b[0m",
      "\u001b[0;31mMySpecialError\u001b[0m                            Traceback (most recent call last)",
      "\u001b[0;32m<ipython-input-23-92c36e04a9d0>\u001b[0m in \u001b[0;36m<module>\u001b[0;34m()\u001b[0m\n\u001b[1;32m      2\u001b[0m     \u001b[0;32mpass\u001b[0m\u001b[0;34m\u001b[0m\u001b[0m\n\u001b[1;32m      3\u001b[0m \u001b[0;34m\u001b[0m\u001b[0m\n\u001b[0;32m----> 4\u001b[0;31m \u001b[0;32mraise\u001b[0m \u001b[0mMySpecialError\u001b[0m\u001b[0;34m(\u001b[0m\u001b[0;34m\"here's the message\"\u001b[0m\u001b[0;34m)\u001b[0m\u001b[0;34m\u001b[0m\u001b[0m\n\u001b[0m",
      "\u001b[0;31mMySpecialError\u001b[0m: here's the message"
     ]
    }
   ],
   "source": [
    "class MySpecialError(ValueError):\n",
    "    pass\n",
    "\n",
    "raise MySpecialError(\"here's the message\")"
   ]
  },
  {
   "cell_type": "markdown",
   "id": "a8dcb55b",
   "metadata": {},
   "source": [
    "This would allow you to use a ``try``...``except`` block that only catches this type of error:"
   ]
  },
  {
   "cell_type": "code",
   "execution_count": 24,
   "id": "80294cb7",
   "metadata": {},
   "outputs": [
    {
     "name": "stdout",
     "output_type": "stream",
     "text": [
      "do something\n",
      "do something else\n"
     ]
    }
   ],
   "source": [
    "try:\n",
    "    print(\"do something\")\n",
    "    raise MySpecialError(\"[informative error message here]\")\n",
    "except MySpecialError:\n",
    "    print(\"do something else\")"
   ]
  },
  {
   "cell_type": "markdown",
   "id": "f070c18c",
   "metadata": {},
   "source": [
    "You might find this useful as you develop more customized code."
   ]
  },
  {
   "cell_type": "markdown",
   "id": "31b51248",
   "metadata": {},
   "source": [
    "## ``try``...``except``...``else``...``finally``\n",
    "\n",
    "\n",
    "In addition to ``try`` and ``except``, you can use the ``else`` and ``finally`` keywords to further tune your code's handling of exceptions.\n",
    "The basic structure is this:\n",
    "![](data/try_except_else_finally.webp)"
   ]
  },
  {
   "cell_type": "code",
   "execution_count": 25,
   "id": "3c8b549a",
   "metadata": {
    "scrolled": true
   },
   "outputs": [
    {
     "name": "stdout",
     "output_type": "stream",
     "text": [
      "try something here\n",
      "this happens only if it succeeds\n",
      "this happens no matter what\n"
     ]
    }
   ],
   "source": [
    "try:\n",
    "    print(\"try something here\")\n",
    "except:\n",
    "    print(\"this happens only if it fails\")\n",
    "else:\n",
    "    print(\"this happens only if it succeeds\")\n",
    "finally:\n",
    "    print(\"this happens no matter what\")"
   ]
  },
  {
   "cell_type": "markdown",
   "id": "f320290a",
   "metadata": {},
   "source": [
    "The utility of ``else`` here is clear, but what's the point of ``finally``?\n",
    "\n",
    "Well, the ``finally`` clause really is executed *no matter what*: I usually see it used to do some sort of cleanup after an operation completes."
   ]
  }
 ],
 "metadata": {
  "kernelspec": {
   "display_name": "Python 3 (ipykernel)",
   "language": "python",
   "name": "python3"
  },
  "language_info": {
   "codemirror_mode": {
    "name": "ipython",
    "version": 3
   },
   "file_extension": ".py",
   "mimetype": "text/x-python",
   "name": "python",
   "nbconvert_exporter": "python",
   "pygments_lexer": "ipython3",
   "version": "3.8.10"
  }
 },
 "nbformat": 4,
 "nbformat_minor": 5
}
